Workbook

Sheet tally_data
A1: Campaign | B1: TallyID | C1: State | D1: LGA | E1: Ward | F1: DateImp | G1: No_settlements | H1: TargetPop | I1: NoTeams | J1: NOHseVist | K1: EligChild | L1: FPZERO | M1: FPOTHER | N1: HSEZERO | O1: HSEOTHER | P1: OUT_school | Q1: OUT_market | R1: OUT_worship | S1: OUT_other | T1: TotalOUTSIDE | U1: Noncompliance_HH | V1: Noncompliance_child | W1: Noncompliance_HH_Revisit | X1: Noncompliance_Child_Revisit | Y1: Noncompliance_HH_pending | Z1: Noncompliance_Child_Pending | AA1: Noncompliance_child_reason | AB1: Absence_HH | AC1: Absence_child | AD1: Absence_HH_Revisit | AE1: Absence_Child_Revisit | AF1: Absence_HH_pending | AG1: Absence_Child_pending | AH1: Children Vaccinated | AI1: Vacc Dosesused | AJ1: Decoded Reason
A2: Round 1 | B2: 1 | C2: Marindi | D2: Adema | E2: Adema 1 | F2: 2026-02-15 | G2: 33 | H2: 1798 | I2: 2 | J2: 1700 | K2: 1895 | L2: 66 | M2: 165 | N2: 87 | O2: 1065 | P2: 50 | Q2: 40 | R2: 75 | S2: 6 | T2: 171 | U2: 2 | V2: 4 | W2: 1 | X2: 2 | Y2: 1 | Z2: 2 | AA2: manyrnd | AB2: 4 | AC2: 6 | AD2: 3 | AE2: 5 | AF2: 1 | AG2: 1 | AH2: 1752 | AI2: 2000 | AJ2: {=IF(AA2="", "", XLOOKUP(AA2, 'Appendix B - Reason codes'!$A$4:$A$14, 'Appendix B - Reason codes'!$B$4:$B$14))} -> Fatigue from many rounds
A3: Round 1 | B3: 2 | C3: Marindi | D3: Adema | E3: Adema 2 | F3: 2026-02-15 | G3: 10 | H3: 3279 | I3: 5 | J3: 2586 | K3: 3418 | L3: 58 | M3: 223 | N3: 137 | O3: 2420 | P3: 4 | Q3: 44 | R3: 7 | S3: 83 | T3: 138 | U3: 3 | V3: 6 | W3: 2 | X3: 5 | Y3: 1 | Z3: 1 | AA3: unhappy | AB3: 2 | AC3: 4 | AD3: 2 | AE3: 3 | AF3: 0 | AG3: 1 | AH3: 3162 | AI3: 3600 | AJ3: {=IF(AA3="", "", XLOOKUP(AA3, 'Appendix B - Reason codes'!$A$4:$A$14, 'Appendix B - Reason codes'!$B$4:$B$14))} -> Unhappy (with the team / programme)
A4: Round 1 | B4: 3 | C4: Marindi | D4: Adema | E4: Adema 3 | F4: 2026-02-15 | G4: 37 | H4: 4882 | I4: 7 | J4: 4059 | K4: 5205 | L4: 28 | M4: 61 | N4: 38 | O4: 3705 | P4: 156 | Q4: 98 | R4: 139 | S4: 102 | T4: 495 | U4: 4 | V4: 6 | W4: 3 | X4: 5 | Y4: 1 | Z4: 1 | AA4: manyrnd | AB4: 2 | AC4: 3 | AD4: 2 | AE4: 2 | AF4: 0 | AG4: 1 | AH4: 4408 | AI4: 4900 | AJ4: {=IF(AA4="", "", XLOOKUP(AA4, 'Appendix B - Reason codes'!$A$4:$A$14, 'Appendix B - Reason codes'!$B$4:$B$14))} -> Fatigue from many rounds
A5: Round 1 | B5: 4 | C5: Marindi | D5: Adema | E5: Adema 4 | F5: 2026-02-15 | G5: 10 | H5: 2836 | I5: 4 | J5: 2721 | K5: 3077 | L5: 34 | M5: 204 | N5: 32 | O5: 2148 | P5: 17 | Q5: 3 | R5: 102 | S5: 9 | T5: 131 | U5: 3 | V5: 6 | W5: 2 | X5: 5 | Y5: 1 | Z5: 1 | AA5: fathernotallowed | AB5: 5 | AC5: 7 | AD5: 4 | AE5: 6 | AF5: 1 | AG5: 1 | AH5: 2674 | AI5: 3000 | AJ5: {=IF(AA5="", "", XLOOKUP(AA5, 'Appendix B - Reason codes'!$A$4:$A$14, 'Appendix B - Reason codes'!$B$4:$B$14))} -> Father didn’t allow
A6: Round 1 | B6: 5 | C6: Marindi | D6: Adema | E6: Adema 5 | F6: 2026-02-15 | G6: 38 | H6: 7073 | I6: 10 | J6: 6350 | K6: 7608 | L6: 49 | M6: 530 | N6: 22 | O6: 3323 | P6: 218 | Q6: 186 | R6: 47 | S6: 41 | T6: 492 | U6: 7 | V6: 15 | W6: 5 | X6: 10 | Y6: 2 | Z6: 5 | AA6: fathernotallowed | AB6: 6 | AC6: 12 | AD6: 5 | AE6: 10 | AF6: 1 | AG6: 2 | AH6: 6032 | AI6: 6850 | AJ6: {=IF(AA6="", "", XLOOKUP(AA6, 'Appendix B - Reason codes'!$A$4:$A$14, 'Appendix B - Reason codes'!$B$4:$B$14))} -> Father didn’t allow
A7: Round 1 | B7: 6 | C7: Marindi | D7: Adema | E7: Adema 6 | F7: 2026-02-15 | G7: 36 | H7: 5795 | I7: 8 | J7: 4811 | K7: 6358 | L7: 68 | M7: 426 | N7: 156 | O7: 4117 | P7: 175 | Q7: 100 | R7: 44 | S7: 122 | T7: 441 | U7: 5 | V7: 10 | W7: 3 | X7: 7 | Y7: 2 | Z7: 3 | AA7: unhappy | AB7: 7 | AC7: 11 | AD7: 5 | AE7: 8 | AF7: 2 | AG7: 3 | AH7: 5059 | AI7: 5650 | AJ7: {=IF(AA7="", "", XLOOKUP(AA7, 'Appendix B - Reason codes'!$A$4:$A$14, 'Appendix B - Reason codes'!$B$4:$B$14))} -> Unhappy (with the team / programme)
A8: Round 1 | B8: 7 | C8: Marindi | D8: Adema | E8: Adema 7 | F8: 2026-02-15 | G8: 34 | H8: 2415 | I8: 3 | J8: 2398 | K8: 2682 | L8: 88 | M8: 179 | N8: 99 | O8: 1259 | P8: 13 | Q8: 35 | R8: 16 | S8: 22 | T8: 86 | U8: 3 | V8: 6 | W8: 2 | X8: 5 | Y8: 1 | Z8: 1 | AA8: unhappy | AB8: 4 | AC8: 6 | AD8: 3 | AE8: 4 | AF8: 1 | AG8: 2 | AH8: 2239 | AI8: 2500 | AJ8: {=IF(AA8="", "", XLOOKUP(AA8, 'Appendix B - Reason codes'!$A$4:$A$14, 'Appendix B - Reason codes'!$B$4:$B$14))} -> Unhappy (with the team / programme)
A9: Round 1 | B9: 8 | C9: Marindi | D9: Adema | E9: Adema 8 | F9: 2026-02-15 | G9: 45 | H9: 7839 | I9: 12 | J9: 6661 | K9: 8674 | L9: 102 | M9: 18 | N9: 225 | O9: 6148 | P9: 101 | Q9: 115 | R9: 131 | S9: 36 | T9: 383 | U9: 6 | V9: 13 | W9: 5 | X9: 11 | Y9: 1 | Z9: 2 | AA9: relbelief | AB9: 7 | AC9: 10 | AD9: 6 | AE9: 9 | AF9: 1 | AG9: 1 | AH9: 7310 | AI9: 8150 | AJ9: {=IF(AA9="", "", XLOOKUP(AA9, 'Appendix B - Reason codes'!$A$4:$A$14, 'Appendix B - Reason codes'!$B$4:$B$14))} -> Religious belief
A10: Round 1 | B10: 9 | C10: Marindi | D10: Adema | E10: Adema 9 | F10: 2026-02-15 | G10: 15 | H10: 6701 | I10: 10 | J10: 6609 | K10: 6992 | L10: 179 | M10: 600 | N10: 146 | O10: 3746 | P10: 313 | Q10: 39 | R10: 291 | S10: 181 | T10: 824 | U10: 1 | V10: 1 | W10: 1 | X10: 1 | Y10: 0 | Z10: 0 | AA10: fathernotallowed | AB10: 9 | AC10: 17 | AD10: 8 | AE10: 15 | AF10: 1 | AG10: 2 | AH10: 6291 | AI10: 6950 | AJ10: {=IF(AA10="", "", XLOOKUP(AA10, 'Appendix B - Reason codes'!$A$4:$A$14, 'Appendix B - Reason codes'!$B$4:$B$14))} -> Father didn’t allow
A11: Round 1 | B11: 10 | C11: Marindi | D11: Adema | E11: Adema 10 | F11: 2026-02-15 | G11: 12 | H11: 5224 | I11: 8 | J11: 3943 | K11: 5780 | L11: 168 | M11: 102 | N11: 13 | O11: 2849 | P11: 215 | Q11: 81 | R11: 9 | S11: 62 | T11: 367 | U11: 3 | V11: 6 | W11: 2 | X11: 4 | Y11: 1 | Z11: 2 | AA11: relbelief | AB11: 2 | AC11: 3 | AD11: 1 | AE11: 2 | AF11: 1 | AG11: 1 | AH11: 4952 | AI11: 5600 | AJ11: {=IF(AA11="", "", XLOOKUP(AA11, 'Appendix B - Reason codes'!$A$4:$A$14, 'Appendix B - Reason codes'!$B$4:$B$14))} -> Religious belief
A12: Round 1 | B12: 11 | C12: Marindi | D12: Belocha | E12: Belocha 1 | F12: 2026-02-15 | G12: 44 | H12: 3056 | I12: 4 | J12: 3035 | K12: 3225 | L12: 107 | M12: 197 | N12: 69 | O12: 1845 | P12: 137 | Q12: 71 | R12: 14 | S12: 24 | T12: 246 | U12: 6 | V12: 13 | W12: 4 | X12: 10 | Y12: 2 | Z12: 3 | AA12: unhappy | AB12: 3 | AC12: 5 | AD12: 3 | AE12: 4 | AF12: 0 | AG12: 1 | AH12: 2922 | AI12: 3150 | AJ12: {=IF(AA12="", "", XLOOKUP(AA12, 'Appendix B - Reason codes'!$A$4:$A$14, 'Appendix B - Reason codes'!$B$4:$B$14))} -> Unhappy (with the team / programme)
A13: Round 1 | B13: 12 | C13: Marindi | D13: Belocha | E13: Belocha 2 | F13: 2026-02-15 | G13: 5 | H13: 1760 | I13: 2 | J13: 1719 | K13: 1950 | L13: 38 | M13: 19 | N13: 46 | O13: 1175 | P13: 68 | Q13: 22 | R13: 24 | S13: 17 | T13: 131 | U13: 1 | V13: 2 | W13: 1 | X13: 1 | Y13: 0 | Z13: 1 | AA13: manyrnd | AB13: 2 | AC13: 3 | AD13: 2 | AE13: 3 | AF13: 0 | AG13: 0 | AH13: 1522 | AI13: 1650 | AJ13: {=IF(AA13="", "", XLOOKUP(AA13, 'Appendix B - Reason codes'!$A$4:$A$14, 'Appendix B - Reason codes'!$B$4:$B$14))} -> Fatigue from many rounds
... A21: Round 1 | B21: 20 | C21: Marindi | D21: Cunda | E21: Cunda 3 | F21: 2026-02-15 | G21: 27 | H21: 1266 | I21: 1 | J21: 1062 | K21: 1361 | L21: 12 | M21: 66 | N21: 18 | O21: 703 | P21: 27 | Q21: 8 | R21: 41 | S21: 25 | T21: 101 | U21: 2 | V21: 3 | W21: 2 | X21: 2 | Y21: 0 | Z21: 1 | AA21: no_reason | AB21: 1 | AC21: 2 | AD21: 1 | AE21: 2 | AF21: 0 | AG21: 0 | AH21: 1102 | AI21: 1250 | AJ21: {=IF(AA21="", "", XLOOKUP(AA21, 'Appendix B - Reason codes'!$A$4:$A$14, 'Appendix B - Reason codes'!$B$4:$B$14))} -> No reason given
A22: Round 1 | B22: 21 | C22: Marindi | D22: Cunda | E22: Cunda 4 | F22: 2026-02-15 | G22: 12 | H22: 440 | I22: 1 | J22: 369 | K22: 460 | L22: 11 | M22: 14 | N22: 0 | O22: 329 | P22: 2 | Q22: 5 | R22: 0 | S22: 10 | T22: 17 | U22: 0 | V22: 0 | W22: 0 | X22: 0 | Y22: 0 | Z22: 0 | AB22: 1 | AC22: 2 | AD22: 1 | AE22: 2 | AF22: 0 | AG22: 0 | AH22: 416 | AI22: 500 | AJ22: {=IF(AA22="", "", XLOOKUP(AA22, 'Appendix B - Reason codes'!$A$4:$A$14, 'Appendix B - Reason codes'!$B$4:$B$14))}
A23: Round 1 | B23: 22 | C23: Marindi | D23: Cunda | E23: Cunda 5 | F23: 2026-02-15 | G23: 37 | H23: 6232 | I23: 9 | J23: 4393 | K23: 6519 | L23: 111 | M23: 536 | N23: 144 | O23: 4696 | P23: 201 | Q23: 213 | R23: 134 | S23: 153 | T23: 701 | U23: 5 | V23: 8 | W23: 4 | X23: 6 | Y23: 1 | Z23: 2 | AA23: no_reason | AB23: 6 | AC23: 12 | AD23: 5 | AE23: 11 | AF23: 1 | AG23: 1 | AH23: 6163 | AI23: 6850 | AJ23: {=IF(AA23="", "", XLOOKUP(AA23, 'Appendix B - Reason codes'!$A$4:$A$14, 'Appendix B - Reason codes'!$B$4:$B$14))} -> No reason given
A24: Round 1 | B24: 23 | C24: Marindi | D24: Cunda | E24: Cunda 6 | F24: 2026-02-15 | G24: 32 | H24: 5958 | I24: 9 | J24: 5054 | K24: 6155 | L24: 9 | M24: 489 | N24: 61 | O24: 4718 | P24: 13 | Q24: 190 | R24: 0 | S24: 43 | T24: 246 | U24: 3 | V24: 6 | W24: 2 | X24: 5 | Y24: 1 | Z24: 1 | AA24: fathernotallowed | AB24: 9 | AC24: 18 | AD24: 8 | AE24: 17 | AF24: 1 | AG24: 1 | AH24: 5653 | AI24: 6250 | AJ24: {=IF(AA24="", "", XLOOKUP(AA24, 'Appendix B - Reason codes'!$A$4:$A$14, 'Appendix B - Reason codes'!$B$4:$B$14))} -> Father didn’t allow
A25: Round 1 | B25: 24 | C25: Marindi | D25: Cunda | E25: Cunda 7 | F25: 2026-02-15 | G25: 50 | H25: 8347 | I25: 12 | J25: 7314 | K25: 9276 | L25: 219 | M25: 11 | N25: 306 | O25: 4992 | P25: 251 | Q25: 128 | R25: 78 | S25: 149 | T25: 606 | U25: 8 | V25: 13 | W25: 6 | X25: 9 | Y25: 2 | Z25: 4 | AA25: adverseeffect | AB25: 9 | AC25: 14 | AD25: 7 | AE25: 12 | AF25: 2 | AG25: 2 | AH25: 7247 | AI25: 7900 | AJ25: {=IF(AA25="", "", XLOOKUP(AA25, 'Appendix B - Reason codes'!$A$4:$A$14, 'Appendix B - Reason codes'!$B$4:$B$14))} -> Concerned about adverse effect
A26: Round 1 | B26: 25 | C26: Marindi | D26: Cunda | E26: Cunda 8 | F26: 2026-02-15 | G26: 32 | H26: 1329 | I26: 2 | J26: 1116 | K26: 1477 | L26: 3 | M26: 85 | N26: 19 | O26: 935 | P26: 23 | Q26: 39 | R26: 55 | S26: 14 | T26: 131 | U26: 2 | V26: 3 | W26: 1 | X26: 2 | Y26: 1 | Z26: 1 | AA26: otherprotection | AB26: 2 | AC26: 3 | AD26: 2 | AE26: 3 | AF26: 0 | AG26: 0 | AH26: 1253 | AI26: 1350 | AJ26: {=IF(AA26="", "", XLOOKUP(AA26, 'Appendix B - Reason codes'!$A$4:$A$14, 'Appendix B - Reason codes'!$B$4:$B$14))} -> Has an alternative to the vaccine
A27: Round 1 | B27: 26 | C27: Marindi | D27: Cunda | E27: Cunda 9 | F27: 2026-02-15 | G27: 23 | H27: 6039 | I27: 9 | J27: 5483 | K27: 6506 | L27: 124 | M27: 476 | N27: 25 | O27: 2859 | P27: 161 | Q27: 200 | R27: 165 | S27: 12 | T27: 538 | U27: 6 | V27: 11 | W27: 4 | X27: 8 | Y27: 2 | Z27: 3 | AA27: relbelief | AB27: 8 | AC27: 16 | AD27: 7 | AE27: 14 | AF27: 1 | AG27: 2 | AH27: 5112 | AI27: 5550 | AJ27: {=IF(AA27="", "", XLOOKUP(AA27, 'Appendix B - Reason codes'!$A$4:$A$14, 'Appendix B - Reason codes'!$B$4:$B$14))} -> Religious belief
A28: Round 1 | B28: 27 | C28: Marindi | D28: Doriga | E28: Doriga 1 | F28: 2026-02-15 | G28: 33 | H28: 7026 | I28: 10 | J28: 5456 | K28: 7742 | L28: 14 | M28: 345 | N28: 212 | O28: 6318 | P28: 296 | Q28: 89 | R28: 185 | S28: 174 | T28: 744 | U28: 5 | V28: 10 | W28: 3 | X28: 6 | Y28: 2 | Z28: 4 | AA28: adverseeffect | AB28: 6 | AC28: 8 | AD28: 5 | AE28: 7 | AF28: 1 | AG28: 1 | AH28: 7448 | AI28: 8500 | AJ28: {=IF(AA28="", "", XLOOKUP(AA28, 'Appendix B - Reason codes'!$A$4:$A$14, 'Appendix B - Reason codes'!$B$4:$B$14))} -> Concerned about adverse effect
A29: Round 1 | B29: 28 | C29: Marindi | D29: Doriga | E29: Doriga 2 | F29: 2026-02-15 | G29: 45 | H29: 11881 | I29: 18 | J29: 11523 | K29: 13062 | L29: 411 | M29: 308 | N29: 334 | O29: 9654 | P29: 180 | Q29: 271 | R29: 153 | S29: 16 | T29: 620 | U29: 14 | V29: 29 | W29: 10 | X29: 21 | Y29: 4 | Z29: 8 | AA29: sick | AB29: 12 | AC29: 22 | AD29: 11 | AE29: 20 | AF29: 1 | AG29: 2 | AH29: 11849 | AI29: 13100 | AJ29: {=IF(AA29="", "", XLOOKUP(AA29, 'Appendix B - Reason codes'!$A$4:$A$14, 'Appendix B - Reason codes'!$B$4:$B$14))} -> Child sick
A30: Round 1 | B30: 29 | C30: Marindi | D30: Doriga | E30: Doriga 3 | F30: 2026-02-15 | G30: 2 | H30: 2052 | I30: 3 | J30: 2021 | K30: 2273 | L30: 41 | M30: 43 | N30: 94 | O30: 1165 | P30: 19 | Q30: 59 | R30: 95 | S30: 34 | T30: 207 | U30: 3 | V30: 5 | W30: 2 | X30: 4 | Y30: 1 | Z30: 1 | AA30: manyrnd | AB30: 2 | AC30: 4 | AD30: 1 | AE30: 3 | AF30: 1 | AG30: 1 | AH30: 1987 | AI30: 2250 | AJ30: {=IF(AA30="", "", XLOOKUP(AA30, 'Appendix B - Reason codes'!$A$4:$A$14, 'Appendix B - Reason codes'!$B$4:$B$14))} -> Fatigue from many rounds
A31: Round 1 | B31: 30 | C31: Marindi | D31: Doriga | E31: Doriga 4 | F31: 2026-02-15 | G31: 24 | H31: 8339 | I31: 12 | J31: 6838 | K31: 9108 | L31: 126 | M31: 86 | N31: 369 | O31: 6533 | P31: 276 | Q31: 148 | R31: 138 | S31: 18 | T31: 580 | U31: 5 | V31: 10 | W31: 3 | X31: 6 | Y31: 2 | Z31: 4 | AA31: fathernotallowed | AB31: 8 | AC31: 15 | AD31: 7 | AE31: 14 | AF31: 1 | AG31: 1 | AH31: 8314 | AI31: 9200 | AJ31: {=IF(AA31="", "", XLOOKUP(AA31, 'Appendix B - Reason codes'!$A$4:$A$14, 'Appendix B - Reason codes'!$B$4:$B$14))} -> Father didn’t allow
A32: Round 1 | B32: 31 | C32: Marindi | D32: Doriga | E32: Doriga 5 | F32: 2026-02-15 | G32: 36 | H32: 10604 | I32: 16 | J32: 7866 | K32: 11361 | L32: 146 | M32: 861 | N32: 392 | O32: 8303 | P32: 326 | Q32: 60 | R32: 159 | S32: 247 | T32: 792 | U32: 8 | V32: 15 | W32: 6 | X32: 10 | Y32: 2 | Z32: 5 | AA32: hascure | AB32: 12 | AC32: 23 | AD32: 9 | AE32: 18 | AF32: 3 | AG32: 5 | AH32: 10791 | AI32: 12450 | AJ32: {=IF(AA32="", "", XLOOKUP(AA32, 'Appendix B - Reason codes'!$A$4:$A$14, 'Appendix B - Reason codes'!$B$4:$B$14))} -> Claims to have a cure
A33: Round 1 | B33: 32 | C33: Marindi | D33: Doriga | E33: Doriga 6 | F33: 2026-02-15 | G33: 37 | H33: 3245 | I33: 4 | J33: 2279 | K33: 3584 | L33: 62 | M33: 27 | N33: 131 | O33: 2613 | P33: 107 | Q33: 121 | R33: 53 | S33: 35 | T33: 316 | U33: 3 | V33: 6 | W33: 2 | X33: 4 | Y33: 1 | Z33: 2 | AA33: fathernotallowed | AB33: 4 | AC33: 7 | AD33: 3 | AE33: 6 | AF33: 1 | AG33: 1 | AH33: 3109 | AI33: 3600 | AJ33: {=IF(AA33="", "", XLOOKUP(AA33, 'Appendix B - Reason codes'!$A$4:$A$14, 'Appendix B - Reason codes'!$B$4:$B$14))} -> Father didn’t allow
A34: Round 1 | B34: 33 | C34: Marindi | D34: Eshwe | E34: Eshwe 1 | F34: 2026-02-15 | G34: 35 | H34: 3819 | I34: 5 | J34: 3570 | K34: 3888 | L34: 12 | M34: 130 | N34: 151 | O34: 1993 | P34: 3 | Q34: 35 | R34: 120 | S34: 59 | T34: 217 | U34: 4 | V34: 6 | W34: 2 | X34: 3 | Y34: 2 | Z34: 3 | AA34: fathernotallowed | AB34: 3 | AC34: 5 | AD34: 2 | AE34: 4 | AF34: 1 | AG34: 1 | AH34: 3563 | AI34: 3950 | AJ34: {=IF(AA34="", "", XLOOKUP(AA34, 'Appendix B - Reason codes'!$A$4:$A$14, 'Appendix B - Reason codes'!$B$4:$B$14))} -> Father didn’t allow
A35: Round 1 | B35: 34 | C35: Marindi | D35: Eshwe | E35: Eshwe 2 | F35: 2026-02-15 | G35: 14 | H35: 2942 | I35: 4 | J35: 2776 | K35: 3108 | L35: 35 | M35: 274 | N35: 68 | O35: 1981 | P35: 79 | Q35: 93 | R35: 5 | S35: 17 | T35: 194 | U35: 0 | V35: 0 | W35: 0 | X35: 0 | Y35: 0 | Z35: 0 | AB35: 4 | AC35: 8 | AD35: 3 | AE35: 6 | AF35: 1 | AG35: 2 | AH35: 2807 | AI35: 3100 | AJ35: {=IF(AA35="", "", XLOOKUP(AA35, 'Appendix B - Reason codes'!$A$4:$A$14, 'Appendix B - Reason codes'!$B$4:$B$14))}
A36: Round 1 | B36: 35 | C36: Marindi | D36: Eshwe | E36: Eshwe 3 | F36: 2026-02-15 | G36: 24 | H36: 17022 | I36: 26 | J36: 15219 | K36: 17494 | L36: 368 | M36: 411 | N36: 604 | O36: 8710 | P36: 118 | Q36: 210 | R36: 170 | S36: 315 | T36: 813 | U36: 13 | V36: 23 | W36: 8 | X36: 15 | Y36: 5 | Z36: 8 | AA36: sick | AB36: 18 | AC36: 30 | AD36: 16 | AE36: 27 | AF36: 2 | AG36: 3 | AH36: 15278 | AI36: 16750 | AJ36: {=IF(AA36="", "", XLOOKUP(AA36, 'Appendix B - Reason codes'!$A$4:$A$14, 'Appendix B - Reason codes'!$B$4:$B$14))} -> Child sick
A37: Round 1 | B37: 36 | C37: Marindi | D37: Eshwe | E37: Eshwe 4 | F37: 2026-02-15 | G37: 13 | H37: 3309 | I37: 5 | J37: 3283 | K37: 3551 | L37: 14 | M37: 9 | N37: 60 | O37: 2011 | P37: 74 | Q37: 110 | R37: 38 | S37: 8 | T37: 230 | U37: 0 | V37: 0 | W37: 0 | X37: 0 | Y37: 0 | Z37: 0 | AB37: 3 | AC37: 6 | AD37: 3 | AE37: 5 | AF37: 0 | AG37: 1 | AH37: 3123 | AI37: 3500 | AJ37: {=IF(AA37="", "", XLOOKUP(AA37, 'Appendix B - Reason codes'!$A$4:$A$14, 'Appendix B - Reason codes'!$B$4:$B$14))}
A38: Round 1 | B38: 37 | C38: Marindi | D38: Eshwe | E38: Eshwe 5 | F38: 2026-02-15 | G38: 39 | H38: 3772 | I38: 5 | J38: 2943 | K38: 4024 | L38: 106 | M38: 129 | N38: 14 | O38: 2667 | P38: 126 | Q38: 113 | R38: 31 | S38: 72 | T38: 342 | U38: 1 | V38: 1 | W38: 1 | X38: 1 | Y38: 0 | Z38: 0 | AA38: adverseeffect | AB38: 6 | AC38: 9 | AD38: 5 | AE38: 7 | AF38: 1 | AG38: 2 | AH38: 3596 | AI38: 3950 | AJ38: {=IF(AA38="", "", XLOOKUP(AA38, 'Appendix B - Reason codes'!$A$4:$A$14, 'Appendix B - Reason codes'!$B$4:$B$14))} -> Concerned about adverse effect
A39: Round 1 | B39: 38 | C39: Marindi | D39: Eshwe | E39: Eshwe 6 | F39: 2026-02-15 | G39: 34 | H39: 13207 | I39: 20 | J39: 9261 | K39: 14114 | L39: 492 | M39: 244 | N39: 580 | O39: 7965 | P39: 99 | Q39: 139 | R39: 299 | S39: 93 | T39: 630 | U39: 15 | V39: 32 | W39: 10 | X39: 22 | Y39: 5 | Z39: 10 | AA39: fathernotallowed | AB39: 15 | AC39: 25 | AD39: 13 | AE39: 21 | AF39: 2 | AG39: 4 | AH39: 12423 | AI39: 13750 | AJ39: {=IF(AA39="", "", XLOOKUP(AA39, 'Appendix B - Reason codes'!$A$4:$A$14, 'Appendix B - Reason codes'!$B$4:$B$14))} -> Father didn’t allow
A40: Round 1 | B40: 39 | C40: Marindi | D40: Eshwe | E40: Eshwe 7 | F40: 2026-02-15 | G40: 11 | H40: 1157 | I40: 1 | J40: 1128 | K40: 1211 | L40: 18 | M40: 4 | N40: 22 | O40: 661 | P40: 20 | Q40: 0 | R40: 6 | S40: 9 | T40: 35 | U40: 2 | V40: 3 | W40: 2 | X40: 2 | Y40: 0 | Z40: 1 | AA40: relbelief | AB40: 2 | AC40: 3 | AD40: 2 | AE40: 3 | AF40: 0 | AG40: 0 | AH40: 1007 | AI40: 1150 | AJ40: {=IF(AA40="", "", XLOOKUP(AA40, 'Appendix B - Reason codes'!$A$4:$A$14, 'Appendix B - Reason codes'!$B$4:$B$14))} -> Religious belief
A41: Round 1 | B41: 40 | C41: Marindi | D41: Eshwe | E41: Eshwe 8 | F41: 2026-02-15 | G41: 12 | H41: 3714 | I41: 5 | J41: 2744 | K41: 3827 | L41: 93 | M41: 103 | N41: 70 | O41: 2105 | P41: 40 | Q41: 134 | R41: 159 | S41: 63 | T41: 396 | U41: 6 | V41: 10 | W41: 5 | X41: 8 | Y41: 1 | Z41: 2 | AA41: adverseeffect | AB41: 1 | AC41: 1 | AD41: 1 | AE41: 1 | AF41: 0 | AG41: 0 | AH41: 3484 | AI41: 3850 | AJ41: {=IF(AA41="", "", XLOOKUP(AA41, 'Appendix B - Reason codes'!$A$4:$A$14, 'Appendix B - Reason codes'!$B$4:$B$14))} -> Concerned about adverse effect
A42: Round 1 | B42: 41 | C42: Marindi | D42: Falpani | E42: Falpani 1 | F42: 2026-02-15 | G42: 48 | H42: 24574 | I42: 37 | J42: 22419 | K42: 25623 | L42: 667 | M42: 938 | N42: 737 | O42: 17049 | P42: 968 | Q42: 194 | R42: 214 | S42: 497 | T42: 1873 | U42: 17 | V42: 32 | W42: 13 | X42: 24 | Y42: 4 | Z42: 8 | AA42: otherprotection | AB42: 32 | AC42: 45 | AD42: 24 | AE42: 34 | AF42: 8 | AG42: 11 | AH42: 21020 | AI42: 23750 | AJ42: {=IF(AA42="", "", XLOOKUP(AA42, 'Appendix B - Reason codes'!$A$4:$A$14, 'Appendix B - Reason codes'!$B$4:$B$14))} -> Has an alternative to the vaccine
A43: Round 1 | B43: 42 | C43: Marindi | D43: Falpani | E43: Falpani 2 | F43: 2026-02-15 | G43: 43 | H43: 14635 | I43: 22 | J43: 14354 | K43: 14792 | L43: 110 | M43: 1142 | N43: 445 | O43: 8720 | P43: 364 | Q43: 265 | R43: 25 | S43: 187 | T43: 841 | U43: 17 | V43: 35 | W43: 11 | X43: 23 | Y43: 6 | Z43: 12 | AA43: sick | AB43: 13 | AC43: 18 | AD43: 11 | AE43: 16 | AF43: 2 | AG43: 2 | AH43: 12594 | AI43: 13900 | AJ43: {=IF(AA43="", "", XLOOKUP(AA43, 'Appendix B - Reason codes'!$A$4:$A$14, 'Appendix B - Reason codes'!$B$4:$B$14))} -> Child sick
A44: Round 1 | B44: 43 | C44: Marindi | D44: Falpani | E44: Falpani 3 | F44: 2026-02-15 | G44: 18 | H44: 9521 | I44: 14 | J44: 6795 | K44: 9527 | L44: 0 | M44: 612 | N44: 319 | O44: 6718 | P44: 87 | Q44: 89 | R44: 326 | S44: 95 | T44: 597 | U44: 13 | V44: 24 | W44: 11 | X44: 20 | Y44: 2 | Z44: 4 | AA44: relbelief | AB44: 8 | AC44: 10 | AD44: 6 | AE44: 8 | AF44: 2 | AG44: 2 | AH44: 8851 | AI44: 9700 | AJ44: {=IF(AA44="", "", XLOOKUP(AA44, 'Appendix B - Reason codes'!$A$4:$A$14, 'Appendix B - Reason codes'!$B$4:$B$14))} -> Religious belief
A45: Round 1 | B45: 44 | C45: Marindi | D45: Falpani | E45: Falpani 4 | F45: 2026-02-15 | G45: 32 | H45: 1882 | I45: 2 | J45: 1466 | K45: 2002 | L45: 67 | M45: 1 | N45: 48 | O45: 1015 | P45: 38 | Q45: 56 | R45: 34 | S45: 26 | T45: 154 | U45: 2 | V45: 4 | W45: 2 | X45: 3 | Y45: 0 | Z45: 1 | AA45: sick | AB45: 1 | AC45: 1 | AD45: 1 | AE45: 1 | AF45: 0 | AG45: 0 | AH45: 1715 | AI45: 1950 | AJ45: {=IF(AA45="", "", XLOOKUP(AA45, 'Appendix B - Reason codes'!$A$4:$A$14, 'Appendix B - Reason codes'!$B$4:$B$14))} -> Child sick
A46: Round 1 | B46: 45 | C46: Marindi | D46: Falpani | E46: Falpani 5 | F46: 2026-02-15 | G46: 42 | H46: 5293 | I46: 8 | J46: 4644 | K46: 5674 | L46: 76 | M46: 91 | N46: 141 | O46: 2900 | P46: 12 | Q46: 150 | R46: 153 | S46: 116 | T46: 431 | U46: 4 | V46: 6 | W46: 3 | X46: 5 | Y46: 1 | Z46: 1 | AA46: fathernotallowed | AB46: 9 | AC46: 17 | AD46: 6 | AE46: 12 | AF46: 3 | AG46: 5 | AH46: 4951 | AI46: 5900 | AJ46: {=IF(AA46="", "", XLOOKUP(AA46, 'Appendix B - Reason codes'!$A$4:$A$14, 'Appendix B - Reason codes'!$B$4:$B$14))} -> Father didn’t allow
A47: Round 1 | B47: 46 | C47: Marindi | D47: Girim | E47: Girim 1 | F47: 2026-02-15 | G47: 15 | H47: 3471 | I47: 5 | J47: 2964 | K47: 3731 | L47: 34 | M47: 90 | N47: 67 | O47: 2321 | P47: 23 | Q47: 76 | R47: 66 | S47: 63 | T47: 228 | U47: 8 | V47: 15 | W47: 6 | X47: 11 | Y47: 2 | Z47: 4 | AA47: relbelief | AB47: 5 | AC47: 9 | AD47: 4 | AE47: 6 | AF47: 1 | AG47: 3 | AH47: 2868 | AI47: 3150 | AJ47: {=IF(AA47="", "", XLOOKUP(AA47, 'Appendix B - Reason codes'!$A$4:$A$14, 'Appendix B - Reason codes'!$B$4:$B$14))} -> Religious belief
...

Sheet Analysis_Summary
A1: Geographic_Level | B1: Round_1_Target Pop | C1: Round_1_Vaccinated | D1: Round_1_Coverage | E1: Round_2_Target Pop | F1: Round_2_Vaccinated | G1: Round_2_Coverage | H1: Coverage_Change
A2: Marindi State | B2: =SUMIFS(tally_data!H:H, tally_data!A:A, "Round 1") -> 573644 | C2: =sumifs(tally_data!AH:AH, tally_data!A:A, "Round 1") -> 531335 | D2: =C2/B2 -> 0.9262452 | E2: =SUMIFS(tally_data!H:H, tally_data!A:A, "Round 2") -> 690426 | F2: =SUMIFS(tally_data!AH:AH, tally_data!A:A, "Round 2") -> 664753 | G2: =F2/E2 -> 0.96281571 | H2: =G2-D2 -> 0.036570514
A3: Adema | B3: =SUMIFS(tally_data!$H:$H, tally_data!$A:$A, "Round 1", tally_data!$D:$D, $A3) -> 47842 | C3: =SUMIFS(tally_data!$AH:$AH, tally_data!$A:$A, "Round 1", tally_data!$D:$D, $A3) -> 43879 | D3: =C3/B3 -> 0.91716483 | E3: =SUMIFS(tally_data!$H:$H, tally_data!$A:$A, "Round 2", tally_data!$D:$D, $A3) -> 65760 | F3: =SUMIFS(tally_data!$AH:$AH, tally_data!$A:$A, "Round 2", tally_data!$D:$D, $A3) -> 64135 | G3: =F3/E3 -> 0.97528893 | H3: =G3-D3 -> 0.058124095
A4: Belocha | B4: =SUMIFS(tally_data!$H:$H, tally_data!$A:$A, "Round 1", tally_data!$D:$D, $A4) -> 71868 | C4: =SUMIFS(tally_data!$AH:$AH, tally_data!$A:$A, "Round 1", tally_data!$D:$D, $A4) -> 65518 | D4: =C4/B4 -> 0.91164357 | E4: =SUMIFS(tally_data!$H:$H, tally_data!$A:$A, "Round 2", tally_data!$D:$D, $A4) -> 67535 | F4: =SUMIFS(tally_data!$AH:$AH, tally_data!$A:$A, "Round 2", tally_data!$D:$D, $A4) -> 65738 | G4: =F4/E4 -> 0.97339157 | H4: =G4-D4 -> 0.061748006
A5: Cunda | B5: =SUMIFS(tally_data!$H:$H, tally_data!$A:$A, "Round 1", tally_data!$D:$D, $A5) -> 36253 | C5: =SUMIFS(tally_data!$AH:$AH, tally_data!$A:$A, "Round 1", tally_data!$D:$D, $A5) -> 32673 | D5: =C5/B5 -> 0.90124955 | E5: =SUMIFS(tally_data!$H:$H, tally_data!$A:$A, "Round 2", tally_data!$D:$D, $A5) -> 102547 | F5: =SUMIFS(tally_data!$AH:$AH, tally_data!$A:$A, "Round 2", tally_data!$D:$D, $A5) -> 98239 | G5: =F5/E5 -> 0.95798999 | H5: =G5-D5 -> 0.056740443
A6: Doriga | B6: =SUMIFS(tally_data!$H:$H, tally_data!$A:$A, "Round 1", tally_data!$D:$D, $A6) -> 43147 | C6: =SUMIFS(tally_data!$AH:$AH, tally_data!$A:$A, "Round 1", tally_data!$D:$D, $A6) -> 43498 | D6: =C6/B6 -> 1.008135 | E6: =SUMIFS(tally_data!$H:$H, tally_data!$A:$A, "Round 2", tally_data!$D:$D, $A6) -> 19088 | F6: =SUMIFS(tally_data!$AH:$AH, tally_data!$A:$A, "Round 2", tally_data!$D:$D, $A6) -> 17610 | G6: =F6/E6 -> 0.92256915 | H6: =G6-D6 -> -0.085565827
A7: Eshwe | B7: =SUMIFS(tally_data!$H:$H, tally_data!$A:$A, "Round 1", tally_data!$D:$D, $A7) -> 48942 | C7: =SUMIFS(tally_data!$AH:$AH, tally_data!$A:$A, "Round 1", tally_data!$D:$D, $A7) -> 45281 | D7: =C7/B7 -> 0.92519717 | E7: =SUMIFS(tally_data!$H:$H, tally_data!$A:$A, "Round 2", tally_data!$D:$D, $A7) -> 58488 | F7: =SUMIFS(tally_data!$AH:$AH, tally_data!$A:$A, "Round 2", tally_data!$D:$D, $A7) -> 56052 | G7: =F7/E7 -> 0.95835043 | H7: =G7-D7 -> 0.033153259
A8: Falpani | B8: =SUMIFS(tally_data!$H:$H, tally_data!$A:$A, "Round 1", tally_data!$D:$D, $A8) -> 55905 | C8: =SUMIFS(tally_data!$AH:$AH, tally_data!$A:$A, "Round 1", tally_data!$D:$D, $A8) -> 49131 | D8: =C8/B8 -> 0.87883016 | E8: =SUMIFS(tally_data!$H:$H, tally_data!$A:$A, "Round 2", tally_data!$D:$D, $A8) -> 36925 | F8: =SUMIFS(tally_data!$AH:$AH, tally_data!$A:$A, "Round 2", tally_data!$D:$D, $A8) -> 35694 | G8: =F8/E8 -> 0.96666215 | H8: =G8-D8 -> 0.087831995
A9: Girim | B9: =SUMIFS(tally_data!$H:$H, tally_data!$A:$A, "Round 1", tally_data!$D:$D, $A9) -> 49879 | C9: =SUMIFS(tally_data!$AH:$AH, tally_data!$A:$A, "Round 1", tally_data!$D:$D, $A9) -> 44465 | D9: =C9/B9 -> 0.89145733 | E9: =SUMIFS(tally_data!$H:$H, tally_data!$A:$A, "Round 2", tally_data!$D:$D, $A9) -> 104188 | F9: =SUMIFS(tally_data!$AH:$AH, tally_data!$A:$A, "Round 2", tally_data!$D:$D, $A9) -> 99923 | G9: =F9/E9 -> 0.95906438 | H9: =G9-D9 -> 0.067607057
A10: Hodu | B10: =SUMIFS(tally_data!$H:$H, tally_data!$A:$A, "Round 1", tally_data!$D:$D, $A10) -> 40415 | C10: =SUMIFS(tally_data!$AH:$AH, tally_data!$A:$A, "Round 1", tally_data!$D:$D, $A10) -> 35595 | D10: =C10/B10 -> 0.88073735 | E10: =SUMIFS(tally_data!$H:$H, tally_data!$A:$A, "Round 2", tally_data!$D:$D, $A10) -> 27679 | F10: =SUMIFS(tally_data!$AH:$AH, tally_data!$A:$A, "Round 2", tally_data!$D:$D, $A10) -> 24270 | G10: =F10/E10 -> 0.87683804 | H10: =G10-D10 -> -0.0038993139
A11: Ilumba | B11: =SUMIFS(tally_data!$H:$H, tally_data!$A:$A, "Round 1", tally_data!$D:$D, $A11) -> 55501 | C11: =SUMIFS(tally_data!$AH:$AH, tally_data!$A:$A, "Round 1", tally_data!$D:$D, $A11) -> 52761 | D11: =C11/B11 -> 0.95063152 | E11: =SUMIFS(tally_data!$H:$H, tally_data!$A:$A, "Round 2", tally_data!$D:$D, $A11) -> 85637 | F11: =SUMIFS(tally_data!$AH:$AH, tally_data!$A:$A, "Round 2", tally_data!$D:$D, $A11) -> 86564 | G11: =F11/E11 -> 1.0108248 | H11: =G11-D11 -> 0.06019324
A12: Jarken | B12: =SUMIFS(tally_data!$H:$H, tally_data!$A:$A, "Round 1", tally_data!$D:$D, $A12) -> 34538 | C12: =SUMIFS(tally_data!$AH:$AH, tally_data!$A:$A, "Round 1", tally_data!$D:$D, $A12) -> 34321 | D12: =C12/B12 -> 0.99371707 | E12: =SUMIFS(tally_data!$H:$H, tally_data!$A:$A, "Round 2", tally_data!$D:$D, $A12) -> 27290 | F12: =SUMIFS(tally_data!$AH:$AH, tally_data!$A:$A, "Round 2", tally_data!$D:$D, $A12) -> 27871 | G12: =F12/E12 -> 1.0212899 | H12: =G12-D12 -> 0.027572784
A13: Kweli | B13: =SUMIFS(tally_data!$H:$H, tally_data!$A:$A, "Round 1", tally_data!$D:$D, $A13) -> 50251 | C13: =SUMIFS(tally_data!$AH:$AH, tally_data!$A:$A, "Round 1", tally_data!$D:$D, $A13) -> 45242 | D13: =C13/B13 -> 0.90032039 | E13: =SUMIFS(tally_data!$H:$H, tally_data!$A:$A, "Round 2", tally_data!$D:$D, $A13) -> 41450 | F13: =SUMIFS(tally_data!$AH:$AH, tally_data!$A:$A, "Round 2", tally_data!$D:$D, $A13) -> 36273 | G13: =F13/E13 -> 0.87510253 | H13: =G13-D13 -> -0.025217858
A14: Lumora | B14: =SUMIFS(tally_data!$H:$H, tally_data!$A:$A, "Round 1", tally_data!$D:$D, $A14) -> 39103 | C14: =SUMIFS(tally_data!$AH:$AH, tally_data!$A:$A, "Round 1", tally_data!$D:$D, $A14) -> 38971 | D14: =C14/B14 -> 0.9966243 | E14: =SUMIFS(tally_data!$H:$H, tally_data!$A:$A, "Round 2", tally_data!$D:$D, $A14) -> 53839 | F14: =SUMIFS(tally_data!$AH:$AH, tally_data!$A:$A, "Round 2", tally_data!$D:$D, $A14) -> 52384 | G14: =F14/E14 -> 0.97297498 | H14: =G14-D14 -> -0.023649319
A17: Non-Compliance Analysis Table
A18: Campaign Round | B18: Total Non-Compliant Children | C18: Total Pending Close | D18: Proportion Pending Close
A19: Round 1 | B19: =SUMIFS(tally_data!V:V, tally_data!A:A, "Round 1") -> 816 | C19: =SUMIFS(tally_data!Z:Z, tally_data!A:A, "Round 1") -> 247 | D19: =C19/B19 -> 0.30269608
A20: Round 2 | B20: =SUMIFS(tally_data!V:V, tally_data!A:A, "Round 2") -> 844 | C20: =SUMIFS(tally_data!Z:Z, tally_data!A:A, "Round 2") -> 99 | D20: =C20/B20 -> 0.11729858
A23: Non-Compliance Reason Breakdown Table
A24: Full Reason Description | B24: Round 1 Non-Compliant Children | C24: Round 2 Non-Compliant Children
A25: Religious belief | B25: =SUMIFS(tally_data!$V:$V, tally_data!$A:$A, "Round 1", tally_data!$AJ:$AJ, $A25) -> 239 | C25: =SUMIFS(tally_data!$V:$V, tally_data!$A:$A, "Round 2", tally_data!$AJ:$AJ, $A25) -> 171
A26: Father didn’t allow | B26: =SUMIFS(tally_data!$V:$V, tally_data!$A:$A, "Round 1", tally_data!$AJ:$AJ, $A26) -> 106 | C26: =SUMIFS(tally_data!$V:$V, tally_data!$A:$A, "Round 2", tally_data!$AJ:$AJ, $A26) -> 148
A27: Fatigue from many rounds | B27: =SUMIFS(tally_data!$V:$V, tally_data!$A:$A, "Round 1", tally_data!$AJ:$AJ, $A27) -> 78 | C27: =SUMIFS(tally_data!$V:$V, tally_data!$A:$A, "Round 2", tally_data!$AJ:$AJ, $A27) -> 108
A28: No reason given | B28: =SUMIFS(tally_data!$V:$V, tally_data!$A:$A, "Round 1", tally_data!$AJ:$AJ, $A28) -> 38 | C28: =SUMIFS(tally_data!$V:$V, tally_data!$A:$A, "Round 2", tally_data!$AJ:$AJ, $A28) -> 93
A29: Child sick | B29: =SUMIFS(tally_data!$V:$V, tally_data!$A:$A, "Round 1", tally_data!$AJ:$AJ, $A29) -> 156 | C29: =SUMIFS(tally_data!$V:$V, tally_data!$A:$A, "Round 2", tally_data!$AJ:$AJ, $A29) -> 50
A30: Unhappy (with the team / programme) | B30: =SUMIFS(tally_data!$V:$V, tally_data!$A:$A, "Round 1", tally_data!$AJ:$AJ, $A30) -> 46 | C30: =SUMIFS(tally_data!$V:$V, tally_data!$A:$A, "Round 2", tally_data!$AJ:$AJ, $A30) -> 96
A31: Concerned about adverse effect | B31: =SUMIFS(tally_data!$V:$V, tally_data!$A:$A, "Round 1", tally_data!$AJ:$AJ, $A31) -> 85 | C31: =SUMIFS(tally_data!$V:$V, tally_data!$A:$A, "Round 2", tally_data!$AJ:$AJ, $A31) -> 41
A32: Has an alternative to the vaccine | B32: =SUMIFS(tally_data!$V:$V, tally_data!$A:$A, "Round 1", tally_data!$AJ:$AJ, $A32) -> 42 | C32: =SUMIFS(tally_data!$V:$V, tally_data!$A:$A, "Round 2", tally_data!$AJ:$AJ, $A32) -> 88
A33: Claims to have a cure | B33: =SUMIFS(tally_data!$V:$V, tally_data!$A:$A, "Round 1", tally_data!$AJ:$AJ, $A33) -> 15 | C33: =SUMIFS(tally_data!$V:$V, tally_data!$A:$A, "Round 2", tally_data!$AJ:$AJ, $A33) -> 46
A34: Other (unspecified) | B34: =SUMIFS(tally_data!$V:$V, tally_data!$A:$A, "Round 1", tally_data!$AJ:$AJ, $A34) -> 11 | C34: =SUMIFS(tally_data!$V:$V, tally_data!$A:$A, "Round 2", tally_data!$AJ:$AJ, $A34) -> 3

Sheet Appendix A - Data dictionary
A1: Appendix A — Data dictionary
A2: One row per ward per round in the tally_data sheet. Not every field is needed for the exercise; part of the task is identifying what is relevant.
A4: Field | B4: Definition
A5: Campaign | B5: Vaccination round this record belongs to (Round 1 or Round 2).
A6: TallyID | B6: Unique ID for each ward-round tally record.
A7: State | B7: State name (Marindi).
A8: LGA | B8: Local Government Area; the mid-level administrative unit.
A9: Ward | B9: Ward; the lowest administrative unit. Each ward appears once per round.
A10: DateImp | B10: Campaign implementation date for the round.
A11: No_settlements | B11: Number of settlements covered in the ward.
A12: TargetPop | B12: Target population: eligible children (0–59 months) planned for vaccination.
A13: NoTeams | B13: Number of vaccination teams deployed.
A14: NOHseVist | B14: Number of houses visited.
A15: EligChild | B15: Eligible children enumerated during the campaign.
... A39: Vacc Dosesused | B39: Total vaccine doses opened/used (administered plus wastage); recorded in multiples of 50, as one vial contains 50 doses.

Sheet Appendix B - Reason codes
A1: Appendix B — Non-compliance reason codes
A2: Codes used in the "Noncompliance_child_reason" column. One predominant reason is recorded per ward; it applies to that ward’s non-compliant children. Blank = no non-compliant children in the ward.
A4: Code | B4: Meaning
A5: relbelief | B5: Religious belief
A6: fathernotallowed | B6: Father didn’t allow
A7: manyrnd | B7: Fatigue from many rounds
A8: no_reason | B8: No reason given
A9: sick | B9: Child sick
A10: unhappy | B10: Unhappy (with the team / programme)
A11: adverseeffect | B11: Concerned about adverse effect
A12: otherprotection | B12: Has an alternative to the vaccine
A13: hascure | B13: Claims to have a cure
A14: other | B14: Other (unspecified)
